<?xml version="1.0"?>
<robot xmlns:xacro="http://ros.org/wiki/xacro" name="rosbot">

    <xacro:include filename="$(find rosbot_description)/urdf/rosbot_gazebo.xacro"/>
    <xacro:include filename="$(find rosbot_description)/urdf/inertial_macros.xacro"/>

  <!-- Base Footprint -->
  <link name="base_footprint"/>
  <joint name="base_joint" type="fixed">
    <parent link="base_footprint"/>
    <child link="base_link"/>
    <origin xyz="0 0 0.04" rpy="0 0 0"/>
  </joint>

  <!-- Base Link -->
  <link name="base_link">
    <visual>
      <origin xyz="0 0 0" rpy="0 0 0"/>
      <geometry>
        <mesh filename="package://rosbot_description/meshes/base_link.stl"/>
      </geometry>
    </visual>
    <collision>
      <origin xyz="0 0 0" rpy="0 0 0"/>
      <geometry>
        <!-- <mesh filename="package://rosbot_description/meshes/base_link.stl"/> -->
       <box size="0.255 0.205 0.150"/>
      </geometry>
    </collision>
    <xacro:inertial_box mass="2" x="0.255" y="0.205" z="0.150">
      <origin xyz="0 0 0" rpy="0 0 0"/>
    </xacro:inertial_box>```
  </link>

  <!-- Left Wheel -->
  <link name="wheel_left_link">
    <visual>
      <origin xyz="0 0 0" rpy=" 0 0 0"/>
      <geometry>
        <!-- <mesh filename="package://rosbot_description/meshes/wheel_left_link.stl"/> -->
        <cylinder radius="0.030" length= "0.0200"/>
      </geometry>
    </visual>
    <collision>
      <origin xyz="1 0 0" rpy="0 0 0"/>
      <geometry>
        <sphere radius="0.030"/>
      </geometry>
    </collision>
    <xacro:inertial_sphere mass="0.01" radius="0.040">
            <origin xyz="0 0 0" rpy="0 0 0"/>
        </xacro:inertial_sphere>
  </link>
<joint name="wheel_left_joint" type="continuous">
    <parent link="base_link"/>
    <child link="wheel_left_link"/>
    <axis xyz="1 0 0"/>
    <origin rpy="0 0 0" xyz="0.07575 0.06100 -0.01750"/>
</joint>

  <!-- Right Wheel -->
  <link name="wheel_right_link">
    <visual>
      <origin xyz="0 0 0" rpy="0 0 0"/>
      <geometry>
        <mesh filename="package://rosbot_description/meshes/wheel_right_link.stl"/>
        <!-- <cylinder radius="0.030" length= "0.0200"/> -->
      </geometry>
    </visual>
    <collision>
      <origin xyz="0 0 0" rpy="0 0 0"/>
      <geometry>
         <sphere radius="0.030"/>
      </geometry>
    </collision>
    <xacro:inertial_sphere mass="0.01" radius="0.040">
            <origin xyz="0 0 0" rpy="0 0 0"/>
        </xacro:inertial_sphere>
  </link>
<joint name="wheel_right_joint" type="continuous">
    <parent link="base_link"/>
    <child link="wheel_right_link"/>
    <axis xyz="1 0 0"/>
    <origin rpy="0 0 3.14" xyz="-0.07575 0.06100 -0.01750"/>
</joint>

  <!-- Caster Wheel -->
  <link name="caster_wheel_link">
    <visual>
      <origin rpy="0 0 1.5708" xyz="0 0 0"/>
      <geometry>
        <mesh filename="package://rosbot_description/meshes/caster_wheel_link.stl"/>
        <!-- <sphere radius="0.030"/> -->
      </geometry>
    </visual>
    <collision>
      <origin xyz="0.02000 -0.09500 0" rpy="0 0 0"/>
      <geometry>
        <sphere radius="0.030"/>   <!-- might need to change -->
      </geometry>
    </collision>
    <xacro:inertial_sphere mass="0.01" radius="0.040">
      <origin xyz="0 0 0" rpy="0 0 0"/>
    </xacro:inertial_sphere>
  </link>
  <joint name="caster_wheel_joint" type="fixed">
    <parent link="base_link"/>
    <child link="caster_wheel_link"/>
    <origin rpy="0 0 0" xyz="0.02000 -0.09500 0"/>
  </joint>

  <!-- LiDAR -->
  <link name="lidar_link">
    <visual>
      <origin xyz="0 0 0" rpy="0 0 0"/>
      <geometry>
        <cylinder radius="0.03" length="0.02"/>
      </geometry>
    </visual>
    <collision>
      <origin xyz="0 0 0" rpy="0 0 0"/>
      <geometry>
        <cylinder radius="0.03" length="0.02"/>
      </geometry>
    </collision>
    <inertial>
      <mass value="0.1"/>
      <inertia ixx="0.0005" ixy="0.0" ixz="0.0"
               iyy="0.0005" iyz="0.0"
               izz="0.0005"/>
      <origin xyz="0 0 0" rpy="0 0 0"/>
    </inertial>
  </link>
  <joint name="lidar_joint" type="fixed">
    <parent link="base_link"/>
    <child link="lidar_link"/>
    <origin xyz="0 0 0.125" rpy="0 0 0"/> <!-- adjust height as needed -->
  </joint>

</robot>